<?xml version="1.0"?>
<robot name="m2d" xmlns:xacro="http://ros.org/wiki/xacro">
	<link name="base_link">
		<visual>
			<origin xyz="-0.13 0 0.51" rpy="0 0 0" />
			<geometry>
				<box size="1.66 0.9 0.55" />
			</geometry>
		</visual>
		<collision>
			<origin xyz="-0.13 0 0.51" rpy="0 0 0" />
			<geometry>
				<box size="1.66 0.9 0.55" />
			</geometry>
		</collision>
		<visual>
			<origin xyz="0 0.375 0" rpy="0 0 0" />
			<geometry>
				<box size="0.9 0.15 0.25" />
			</geometry>
		</visual>
		<collision>
			<origin xyz="0 0.375 0" rpy="0 0 0" />
			<geometry>
				<box size="0.9 0.15 0.25" />
			</geometry>
		</collision>
		<visual>
			<origin xyz="0 -0.375 0" rpy="0 0 0" />
			<geometry>
				<box size="0.9 0.15 0.25" />
			</geometry>
		</visual>
		<collision>
			<origin xyz="0 -0.375 0" rpy="0 0 0" />
			<geometry>
				<box size="0.9 0.15 0.25" />
			</geometry>
		</collision>
		<visual>
			<origin xyz="-0.82 0 0.025" rpy="0 0 0" />
			<geometry>
				<box size="0.535 0.45 0.3" />
			</geometry>
		</visual>
		<collision>
			<origin xyz="-0.82 0 0.025" rpy="0 0 0" />
			<geometry>
				<box size="0.535 0.45 0.3" />
			</geometry>
		</collision>
		<visual>
			<origin xyz="0.82 0 0.025" rpy="0 0 0" />
			<geometry>
				<box size="0.535 0.45 0.3" />
			</geometry>
		</visual>
		<collision>
			<origin xyz="0.82 0 0.025" rpy="0 0 0" />
			<geometry>
				<box size="0.535 0.45 0.3" />
			</geometry>
		</collision>
	</link>

	<link name="lidar">
		<visual>
			<origin xyz="0 0 -0.005" rpy="0 0 0" />
			<geometry>
				<cylinder radius="0.02" length="0.07" />
			</geometry>
		</visual>
		<collision>
			<origin xyz="0 0 -0.005" rpy="0 0 0" />
			<geometry>
				<cylinder radius="0.02" length="0.07" />
			</geometry>
		</collision>
	</link>

	<joint name="base_link_lidar_joint" type="fixed">
		<parent link="base_link" />
		<child link="lidar" />
		<origin xyz="0.425 0 0.84" rpy="0 0 0" />
	</joint>

	<link name="Front_Camera">
		<visual>
			<origin xyz="-0.01 0 0" rpy="0 0 0" />
			<geometry>
				<cylinder radius="0.01" length="0.02" />
			</geometry>
		</visual>
		<collision>
			<origin xyz="-0.01 0 0" rpy="0 0 0" />
			<geometry>
				<cylinder radius="0.01" length="0.02" />
			</geometry>
		</collision>
	</link>

	<joint name="base_link_Front_Camera_joint" type="fixed">
		<parent link="base_link" />
		<child link="Front_Camera" />
		<origin xyz="0.48632 0 1.04663" rpy="-1.570796 0.3927 -1.570796" />
	</joint>



	<link name="back_left_wheel">
		<visual>
			<origin xyz="0 0 0" rpy="0.0 0.0 0.0" />
			<geometry>
				<cylinder radius="0.261" length="0.205" />
			</geometry>
		</visual>
		<collision>
			<origin xyz="0 0 0" rpy="0.0 0.0 0.0" />
			<geometry>
				<cylinder radius="0.261" length="0.205" />
			</geometry>
		</collision>
	</link>

  <!-- <joint name="steering_motor_bl" type="revolute">
		<parent link="base_link" />
		<child link="back left wheel" />
		<axis xyz="0 0 1" />
		<limit effort="200" lower="-1.5" upper="1.5" velocity="0.4" />
		<origin xyz="-0.7725 0.607 0" rpy="0 0 1.571813" />
	</joint> -->

  <joint name="steering_motor_bl" type="continuous">
    <parent link="base_link"/>
    <child link="back_left_wheel"/>
    <axis xyz="0 0 1"/>
    <origin xyz="0 0 0.261" rpy="0 1.57 1.57"/>
  </joint>
  
<!-- 
	<link name="back left wheel_0">
    <visual>
      <origin xyz="0 0 0" rpy="0 1.570796 0" />
			<geometry>
        <cylinder radius="0.261" length="0.205" />
			</geometry>
		</visual>
		<collision>
      <origin xyz="0 0 0" rpy="0 1.570796 0" />
			<geometry>
        <cylinder radius="0.261" length="0.205" />
			</geometry>
		</collision>
	</link> -->
  
  <!-- <joint name="drive_motor_bl" type="continuous">
    <parent link="base_link" />
    <child link="back left wheel" />
    <axis xyz="1 0 0" />
    <limit effort="250" velocity="27" />
    <origin xyz="0 0 0" rpy="0.146793 0 0" />
  </joint> -->
<!--   
	<joint name="steering_motor_br" type="revolute">
		<parent link="base_link" />
		<child link="back right wheel" />
		<axis xyz="0 -0.000141 1" />
		<limit effort="200" lower="-0.5" upper="0.5" velocity="0.4" />
		<origin xyz="-0.7725 -0.607 0" rpy="-0.000141 0 1.570776" />
	</joint>

	<link name="back right wheel">
		<visual>
			<origin xyz="0 0 0" rpy="3.141593 -1.570793 3.141593" />
			<geometry>
				<cylinder radius="0.05" length="0.1" />
			</geometry>
		</visual>
		<collision>
			<origin xyz="0 0 0" rpy="3.141593 -1.570793 3.141593" />
			<geometry>
				<cylinder radius="0.05" length="0.1" />
			</geometry>
		</collision>
	</link>

	<joint name="drive_motor_br" type="continuous">
		<parent link="back right wheel" />
		<child link="back right wheel_1" />
		<axis xyz="1 0 0" />
		<limit effort="250" velocity="27" />
		<origin xyz="0 0 0" rpy="0.144756 0 0" />
	</joint>

	<link name="back right wheel_1">
		<visual>
			<origin xyz="0 0 0" rpy="0 1.570796 0" />
			<geometry>
				<cylinder radius="0.261" length="0.205" />
			</geometry>
		</visual>
		<collision>
			<origin xyz="0 0 0" rpy="0 1.570796 0" />
			<geometry>
				<cylinder radius="0.261" length="0.205" />
			</geometry>
		</collision>
	</link>

	<joint name="steering_motor_fr" type="revolute">
		<parent link="base_link" />
		<child link="front right wheel" />
		<axis xyz="0 0 1" />
		<limit effort="200" lower="-0.5" upper="0.5" velocity="0.4" />
		<origin xyz="0.7725 -0.607 0" rpy="0 0 1.569235" />
	</joint>

	<link name="front right wheel">
		<visual>
			<origin xyz="0 0 0" rpy="3.141593 -1.570793 3.141593" />
			<geometry>
				<cylinder radius="0.05" length="0.1" />
			</geometry>
		</visual>
		<collision>
			<origin xyz="0 0 0" rpy="3.141593 -1.570793 3.141593" />
			<geometry>
				<cylinder radius="0.05" length="0.1" />
			</geometry>
		</collision>
	</link>

	<joint name="drive_motor_fr" type="continuous">
		<parent link="front right wheel" />
		<child link="front right wheel_2" />
		<axis xyz="1 0 0" />
		<limit effort="200" velocity="27" />
		<origin xyz="0 0 0" rpy="0.67099 0 0" />
	</joint>

	<link name="front right wheel_2">
		<visual>
			<origin xyz="0 0 0" rpy="0 1.570796 0" />
			<geometry>
				<cylinder radius="0.261" length="0.205" />
			</geometry>
		</visual>
		<collision>
			<origin xyz="0 0 0" rpy="0 1.570796 0" />
			<geometry>
				<cylinder radius="0.261" length="0.205" />
			</geometry>
		</collision>
	</link>

	<joint name="steering_motor_fl" type="revolute">
		<parent link="base_link" />
		<child link="front left wheel" />
		<axis xyz="0 0 1" />
		<limit effort="200" lower="-0.5" upper="0.5" velocity="0.4" />
		<origin xyz="0.7725 0.607 0" rpy="0 0 -1.570385" />
	</joint>

	<link name="front left wheel">
		<visual>
			<origin xyz="0 0 0" rpy="3.141593 -1.570793 3.141593" />
			<geometry>
				<cylinder radius="0.05" length="0.1" />
			</geometry>
		</visual>
		<collision>
			<origin xyz="0 0 0" rpy="3.141593 -1.570793 3.141593" />
			<geometry>
				<cylinder radius="0.05" length="0.1" />
			</geometry>
		</collision>
	</link>

	<joint name="drive_motor_fl" type="continuous">
		<parent link="front left wheel" />
		<child link="front left wheel_3" />
		<axis xyz="-1 0 0" />
		<limit effort="200" velocity="27" />
		<origin xyz="0 0 0" rpy="-0.673929 0 0" />
	</joint>

	<link name="front left wheel_3">
		<visual>
			<origin xyz="0 0 0" rpy="0 1.570796 0" />
			<geometry>
				<cylinder radius="0.261" length="0.205" />
			</geometry>
		</visual>
		<collision>
			<origin xyz="0 0 0" rpy="0 1.570796 0" />
			<geometry>
				<cylinder radius="0.261" length="0.205" />
			</geometry>
		</collision>
	</link> -->

</robot>
